---

## ⚠️ 문제 18 - Java 예외 처리 흐름 분석

> 📌 **문제 설명**
> 다음 Java 코드를 실행했을 때 출력되는 값을 작성하시오.

---

### 📄 문제 코드

```java
public class ExceptionHandling {
  public static void main(String[] args) {
    int sum = 0;
    try {
        func();
    } catch (NullPointerException e) {
        sum = sum + 1;
    } catch (Exception e) {
        sum = sum + 10;
    } finally {
        sum = sum + 100;
    }
    System.out.print(sum);
  }

  static void func() throws Exception {
    throw new NullPointerException(); 
  }
}
```

---

### 🔍 문제 분석

#### ✅ 예외 발생 시점

```java
func(); // 호출됨과 동시에 예외 발생
```

* `func()`는 `Exception`을 던질 수 있도록 선언됨 (`throws Exception`)
* 실제로는 `throw new NullPointerException();` 발생
  → 이는 **Exception의 하위 클래스**

---

### ✅ 예외 처리 흐름

* `try`에서 예외 발생

* 가장 먼저 **`catch (NullPointerException e)`** 블록 실행
  → `sum += 1`

* 그 후 `finally` 블록 실행
  → `sum += 100`

🔸 `catch (Exception e)`는 실행되지 않음.
(이미 NullPointerException에서 잡았기 때문)

---

### ✅ 최종 계산

```java
sum = 0 + 1 (catch) + 100 (finally) = 101
```

---

### ✅ 최종 출력 결과

```
101
```

---

### 💡 해설 요약

| 항목        | 설명                                     |
| --------- | -------------------------------------- |
| 예외 발생     | `NullPointerException` 발생              |
| 예외 처리     | `catch (NullPointerException e)`에서 처리됨 |
| `finally` | 항상 실행됨                                 |
| 최종 합      | `1 + 100 = 101`                        |

---

### 📘 관련 개념 정리

| 개념                  | 설명                                                 |
| ------------------- | -------------------------------------------------- |
| `try-catch-finally` | 예외 발생 시 흐름 제어                                      |
| `throw`             | 명시적으로 예외를 발생시킴                                     |
| 예외 계층 구조            | `NullPointerException`은 `RuntimeException`의 하위 클래스 |
| `finally`           | 예외 발생 여부와 관계없이 **무조건 실행**                          |

---